Workbook

Sheet 📦 Productos
A1: 🏪 CATÁLOGO DE PRODUCTOS
A2: Ingresa aquí todos tus productos con costos y precios. El margen se calcula automáticamente.
A3: # | B3: Producto | C3: Categoría | D3: Unidad | E3: Costo ($) | F3: Precio Venta ($) | G3: Margen ($) | H3: Margen (%)
B4: (1kg) Aceituna Natural | C4: Aceitunas | D4: 1kg | E4: 4900 | F4: 8000 | G4: =F4-E4 -> 3100 | H4: =IF(F4>0,(F4-E4)/F4,0) -> 0.3875
B5: (250g) Aceituna Amarga | C5: Aceitunas | D5: 250g | E5: 2050 | F5: 3500 | G5: =F5-E5 -> 1450 | H5: =IF(F5>0,(F5-E5)/F5,0) -> 0.41428571
B6: (250g) Aceituna Natural | C6: Aceitunas | D6: 250g | E6: 1900 | F6: 3500 | G6: =F6-E6 -> 1600 | H6: =IF(F6>0,(F6-E6)/F6,0) -> 0.45714286
B7: (250g) Aceituna rellena | C7: Aceitunas | D7: 250g | E7: 1900 | F7: 3790 | G7: =F7-E7 -> 1890 | H7: =IF(F7>0,(F7-E7)/F7,0) -> 0.49868074
B8: (250g) Pickle | C8: Aceitunas | D8: 250g | E8: 1650 | F8: 3290 | G8: =F8-E8 -> 1640 | H8: =IF(F8>0,(F8-E8)/F8,0) -> 0.49848024
B9: (500g) Aceituna Amarga | C9: Aceitunas | D9: 500g | E9: 3100 | F9: 4800 | G9: =F9-E9 -> 1700 | H9: =IF(F9>0,(F9-E9)/F9,0) -> 0.35416667
B10: (500g) Aceituna Natural | C10: Aceitunas | D10: 500g | E10: 2900 | F10: 5000 | G10: =F10-E10 -> 2100 | H10: =IF(F10>0,(F10-E10)/F10,0) -> 0.42
B11: (500g) Aceituna Rellena | C11: Aceitunas | D11: 500g | E11: 2900 | F11: 5890 | G11: =F11-E11 -> 2990 | H11: =IF(F11>0,(F11-E11)/F11,0) -> 0.50764007
B12: (500g) Pickle | C12: Aceitunas | D12: 500g | E12: 1800 | F12: 4390 | G12: =F12-E12 -> 2590 | H12: =IF(F12>0,(F12-E12)/F12,0) -> 0.58997722
A13: 57 | B13: Chorizo Parrilero 1/2 kg | C13: Embutidos | D13: 1/2 kg | E13: 3064 | F13: 5500 | G13: =F13-E13 -> 2436 | H13: =IF(F13>0,(F13-E13)/F13,0) -> 0.44290909
A14: 56 | B14: Chorizo Parrilero 1kg | C14: Embutidos | D14: 1kg | E14: 5409 | F14: 8000 | G14: =F14-E14 -> 2591 | H14: =IF(F14>0,(F14-E14)/F14,0) -> 0.323875
A15: 53 | B15: Longaniza Ahumada 1/2 kg | C15: Embutidos | D15: 1/2 kg | E15: 3064 | F15: 5500 | G15: =F15-E15 -> 2436 | H15: =IF(F15>0,(F15-E15)/F15,0) -> 0.44290909
A16: 52 | B16: Longaniza Ahumada 1kg | C16: Embutidos | D16: 1kg | E16: 5409 | F16: 8000 | G16: =F16-E16 -> 2591 | H16: =IF(F16>0,(F16-E16)/F16,0) -> 0.323875
A17: 55 | B17: Longaniza Tradicional 1/2 kg | C17: Embutidos | D17: 1/2 kg | E17: 3064 | F17: 5500 | G17: =F17-E17 -> 2436 | H17: =IF(F17>0,(F17-E17)/F17,0) -> 0.44290909
A18: 54 | B18: Longaniza Tradicional 1kg | C18: Embutidos | D18: 1kg | E18: 5409 | F18: 8000 | G18: =F18-E18 -> 2591 | H18: =IF(F18>0,(F18-E18)/F18,0) -> 0.323875
A19: 32 | B19: Almendras 100g | C19: Frutos Secos | D19: 100g | E19: 1060 | F19: 1600 | G19: =F19-E19 -> 540 | H19: =IF(F19>0,(F19-E19)/F19,0) -> 0.3375
A20: 35 | B20: Almendras 1kg | C20: Frutos Secos | D20: 1kg | E20: 10600 | F20: 14250 | G20: =F20-E20 -> 3650 | H20: =IF(F20>0,(F20-E20)/F20,0) -> 0.25614035
A21: 33 | B21: Almendras 250g | C21: Frutos Secos | D21: 250g | E21: 2650 | F21: 3750 | G21: =F21-E21 -> 1100 | H21: =IF(F21>0,(F21-E21)/F21,0) -> 0.29333333
A22: 34 | B22: Almendras 500g | C22: Frutos Secos | D22: 500g | E22: 5300 | F22: 7350 | G22: =F22-E22 -> 2050 | H22: =IF(F22>0,(F22-E22)/F22,0) -> 0.27891156
A23: 40 | B23: Castaña de Cajú 100g | C23: Frutos Secos | D23: 100g | E23: 1350 | F23: 2400 | G23: =F23-E23 -> 1050 | H23: =IF(F23>0,(F23-E23)/F23,0) -> 0.4375
A24: 43 | B24: Castaña de Cajú 1kg | C24: Frutos Secos | D24: 1kg | E24: 13500 | F24: 19900 | G24: =F24-E24 -> 6400 | H24: =IF(F24>0,(F24-E24)/F24,0) -> 0.32160804
... A62: 27 | B62: Mantequilla Rumay | C62: Mantequillas | D62: Unidad | E62: 1726 | F62: 2800 | G62: =F62-E62 -> 1074 | H62: =IF(F62>0,(F62-E62)/F62,0) -> 0.38357143
B63: 0% Frutos del bosque | C63: Mermeladas | D63: Unidad | E63: 2023 | F63: 3500 | G63: =F63-E63 -> 1477 | H63: =IF(F63>0,(F63-E63)/F63,0) -> 0.422
B64: Arandano linaza | C64: Mermeladas | D64: Unidad | E64: 2023 | F64: 3500 | G64: =F64-E64 -> 1477 | H64: =IF(F64>0,(F64-E64)/F64,0) -> 0.422
B65: Chimichurri | C65: Mermeladas | D65: Unidad | E65: 2023 | F65: 3500 | G65: =F65-E65 -> 1477 | H65: =IF(F65>0,(F65-E65)/F65,0) -> 0.422
B66: frutos del bosque | C66: Mermeladas | D66: Unidad | E66: 2023 | F66: 3500 | G66: =F66-E66 -> 1477 | H66: =IF(F66>0,(F66-E66)/F66,0) -> 0.422
B67: Mora, menta, limon | C67: Mermeladas | D67: Unidad | E67: 2023 | F67: 3500 | G67: =F67-E67 -> 1477 | H67: =IF(F67>0,(F67-E67)/F67,0) -> 0.422
B68: naranja canrla | C68: Mermeladas | D68: Unidad | E68: 2023 | F68: 3500 | G68: =F68-E68 -> 1477 | H68: =IF(F68>0,(F68-E68)/F68,0) -> 0.422
B69: Piña,jenjibre, menta | C69: Mermeladas | D69: Unidad | E69: 2023 | F69: 3500 | G69: =F69-E69 -> 1477 | H69: =IF(F69>0,(F69-E69)/F69,0) -> 0.422
B70: Albahaca 200g | C70: QuesoCabra | D70: 200g | E70: 3891 | F70: 5500 | G70: =F70-E70 -> 1609 | H70: =IF(F70>0,(F70-E70)/F70,0) -> 0.29254545
B71: Albahaca 420g | C71: QuesoCabra | D71: 420g | E71: 7489 | F71: 9500 | G71: =F71-E71 -> 2011 | H71: =IF(F71>0,(F71-E71)/F71,0) -> 0.21168421
B72: Merken 200g | C72: QuesoCabra | D72: 200g | E72: 3891 | F72: 5500 | G72: =F72-E72 -> 1609 | H72: =IF(F72>0,(F72-E72)/F72,0) -> 0.29254545
B73: Merken 420g | C73: QuesoCabra | D73: 420g | E73: 7489 | F73: 9500 | G73: =F73-E73 -> 2011 | H73: =IF(F73>0,(F73-E73)/F73,0) -> 0.21168421
B74: Natural200g | C74: QuesoCabra | D74: 200g | E74: 3831.8 | F74: 5500 | G74: =F74-E74 -> 1668.2 | H74: =IF(F74>0,(F74-E74)/F74,0) -> 0.30330909
... B76: Ahumado 200g | C76: Quesos | D76: 200g | E76: 2499 | F76: 5000 | G76: =F76-E76 -> 2501 | H76: =IF(F76>0,(F76-E76)/F76,0) -> 0.5002
A77: 22 | B77: Albahaca 200g | C77: Quesos | D77: 200g | E77: 2499 | F77: 5000 | G77: =F77-E77 -> 2501 | H77: =IF(F77>0,(F77-E77)/F77,0) -> 0.5002
B78: Laminado 220g | C78: Quesos | D78: 220g | E78: 1900 | F78: 4500 | G78: =F78-E78 -> 2600 | H78: =IF(F78>0,(F78-E78)/F78,0) -> 0.57777778
...

Sheet 🛒 Ventas del Día
A1: 🛒 REGISTRO DE VENTAS DIARIAS
A2: Ingresa cada venta: selecciona la fecha, el producto y la cantidad vendida. Los totales se calculan automáticamente.
A3: Nº Boleta | B3: Fecha | C3: Categoría | D3: Producto | E3: Precio ($) | F3: Cantidad | G3: Total Venta ($) | H3: Costo Total ($) | I3: Ganancia ($) | J3: Método Pago | K3: Total Boleta
B4: 46176 | C4: Huevos | D4: Huevo Extra 30u | E4: =IFERROR(VLOOKUP(D4,'📦 Productos'!B:F,5,0),"") -> 8550 | F4: 2 | G4: =IFERROR(IF(E4*F4>0,E4*F4,""),"") -> 17100 | H4: =IFERROR(VLOOKUP(D4,'📦 Productos'!B:E,4,0)*F4,0) -> 12634 | I4: =IFERROR(IF(ISNUMBER(G4),G4-H4,""),"") -> 4466 | K4: =IF(A4<>"",SUMIF($A$4:$A$107,A4,$G$4:$G$107),"")
B5: 46176 | C5: Huevos | D5: Huevo Extra 30u | E5: =IFERROR(VLOOKUP(D5,'📦 Productos'!B:F,5,0),"") -> 8550 | F5: 1 | G5: =IFERROR(IF(E5*F5>0,E5*F5,""),"") -> 8550 | H5: =IFERROR(VLOOKUP(D5,'📦 Productos'!B:E,4,0)*F5,0) -> 6317 | I5: =IFERROR(IF(ISNUMBER(G5),G5-H5,""),"") -> 2233 | K5: =IF(A5<>"",SUMIF($A$4:$A$107,A5,$G$4:$G$107),"")
B6: 46176 | C6: Frutos Secos | D6: Almendras 100g | E6: =IFERROR(VLOOKUP(D6,'📦 Productos'!B:F,5,0),"") -> 1600 | F6: 1 | G6: =IFERROR(IF(E6*F6>0,E6*F6,""),"") -> 1600 | H6: =IFERROR(VLOOKUP(D6,'📦 Productos'!B:E,4,0)*F6,0) -> 1060 | I6: =IFERROR(IF(ISNUMBER(G6),G6-H6,""),"") -> 540 | K6: =IF(A6<>"",SUMIF($A$4:$A$107,A6,$G$4:$G$107),"")
B7: 46176 | C7: Frutos Secos | D7: Mix Regodión 100g | E7: =IFERROR(VLOOKUP(D7,'📦 Productos'!B:F,5,0),"") -> 1200 | F7: 1 | G7: =IFERROR(IF(E7*F7>0,E7*F7,""),"") -> 1200 | H7: =IFERROR(VLOOKUP(D7,'📦 Productos'!B:E,4,0)*F7,0) -> 580 | I7: =IFERROR(IF(ISNUMBER(G7),G7-H7,""),"") -> 620 | K7: =IF(A7<>"",SUMIF($A$4:$A$107,A7,$G$4:$G$107),"")
B8: 46176 | C8: Huevos | D8: Huevo Primera 6u | E8: =IFERROR(VLOOKUP(D8,'📦 Productos'!B:F,5,0),"") -> 1950 | F8: 1 | G8: =IFERROR(IF(E8*F8>0,E8*F8,""),"") -> 1950 | H8: =IFERROR(VLOOKUP(D8,'📦 Productos'!B:E,4,0)*F8,0) -> 1163 | I8: =IFERROR(IF(ISNUMBER(G8),G8-H8,""),"") -> 787 | K8: =IF(A8<>"",SUMIF($A$4:$A$107,A8,$G$4:$G$107),"")
B9: 46176 | C9: Frutos Secos | D9: Mix Regodión 250g | E9: =IFERROR(VLOOKUP(D9,'📦 Productos'!B:F,5,0),"") -> 2300 | F9: 1 | G9: =IFERROR(IF(E9*F9>0,E9*F9,""),"") -> 2300 | H9: =IFERROR(VLOOKUP(D9,'📦 Productos'!B:E,4,0)*F9,0) -> 1450 | I9: =IFERROR(IF(ISNUMBER(G9),G9-H9,""),"") -> 850 | K9: =IF(A9<>"",SUMIF($A$4:$A$107,A9,$G$4:$G$107),"")
B10: 46176 | C10: Huevos | D10: Huevo Extra 30u | E10: =IFERROR(VLOOKUP(D10,'📦 Productos'!B:F,5,0),"") -> 8550 | F10: 1 | G10: =IFERROR(IF(E10*F10>0,E10*F10,""),"") -> 8550 | H10: =IFERROR(VLOOKUP(D10,'📦 Productos'!B:E,4,0)*F10,0) -> 6317 | I10: =IFERROR(IF(ISNUMBER(G10),G10-H10,""),"") -> 2233 | K10: =IF(A10<>"",SUMIF($A$4:$A$107,A10,$G$4:$G$107),"")
B11: 46176 | C11: Huevos | D11: Huevo Primera 30u | E11: =IFERROR(VLOOKUP(D11,'📦 Productos'!B:F,5,0),"") -> 7800 | F11: 1 | G11: =IFERROR(IF(E11*F11>0,E11*F11,""),"") -> 7800 | H11: =IFERROR(VLOOKUP(D11,'📦 Productos'!B:E,4,0)*F11,0) -> 5817 | I11: =IFERROR(IF(ISNUMBER(G11),G11-H11,""),"") -> 1983 | K11: =IF(A11<>"",SUMIF($A$4:$A$107,A11,$G$4:$G$107),"")
B12: 46176 | C12: Huevos | D12: Huevo Super 30u | E12: =IFERROR(VLOOKUP(D12,'📦 Productos'!B:F,5,0),"") -> 10000 | F12: 2 | G12: =IFERROR(IF(E12*F12>0,E12*F12,""),"") -> 20000 | H12: =IFERROR(VLOOKUP(D12,'📦 Productos'!B:E,4,0)*F12,0) -> 16200 | I12: =IFERROR(IF(ISNUMBER(G12),G12-H12,""),"") -> 3800 | K12: =IF(A12<>"",SUMIF($A$4:$A$107,A12,$G$4:$G$107),"")
B13: 46177 | C13: Frutos Secos | D13: Nueces 100g | E13: =IFERROR(VLOOKUP(D13,'📦 Productos'!B:F,5,0),"") -> 1500 | F13: 1 | G13: =IFERROR(IF(E13*F13>0,E13*F13,""),"") -> 1500 | H13: =IFERROR(VLOOKUP(D13,'📦 Productos'!B:E,4,0)*F13,0) -> 847 | I13: =IFERROR(IF(ISNUMBER(G13),G13-H13,""),"") -> 653 | K13: =IF(A13<>"",SUMIF($A$4:$A$107,A13,$G$4:$G$107),"")
B14: 46177 | C14: Frutos Secos | D14: Maní sin Sal 1kg | E14: =IFERROR(VLOOKUP(D14,'📦 Productos'!B:F,5,0),"") -> 4750 | F14: 1 | G14: =IFERROR(IF(E14*F14>0,E14*F14,""),"") -> 4750 | H14: =IFERROR(VLOOKUP(D14,'📦 Productos'!B:E,4,0)*F14,0) -> 3410 | I14: =IFERROR(IF(ISNUMBER(G14),G14-H14,""),"") -> 1340 | J14: Tarjeta | K14: =IF(A14<>"",SUMIF($A$4:$A$107,A14,$G$4:$G$107),"")
B15: 46177 | C15: Huevos | D15: Huevo Extra 30u | E15: =IFERROR(VLOOKUP(D15,'📦 Productos'!B:F,5,0),"") -> 8550 | F15: 1 | G15: =IFERROR(IF(E15*F15>0,E15*F15,""),"") -> 8550 | H15: =IFERROR(VLOOKUP(D15,'📦 Productos'!B:E,4,0)*F15,0) -> 6317 | I15: =IFERROR(IF(ISNUMBER(G15),G15-H15,""),"") -> 2233 | J15: Tarjeta | K15: =IF(A15<>"",SUMIF($A$4:$A$107,A15,$G$4:$G$107),"")
B16: 46177 | C16: Quesos | D16: Runca 500g | E16: 7500 | F16: 1 | G16: =IFERROR(IF(E16*F16>0,E16*F16,""),"") -> 7500 | H16: =IFERROR(VLOOKUP(D16,'📦 Productos'!B:E,4,0)*F16,0) -> 5117 | I16: =IFERROR(IF(ISNUMBER(G16),G16-H16,""),"") -> 2383 | J16: Tarjeta | K16: =IF(A16<>"",SUMIF($A$4:$A$107,A16,$G$4:$G$107),"")
B17: 46177 | C17: Huevos | D17: Huevo Primera 30u | E17: =IFERROR(VLOOKUP(D17,'📦 Productos'!B:F,5,0),"") -> 7800 | F17: 2 | G17: =IFERROR(IF(E17*F17>0,E17*F17,""),"") -> 15600 | H17: =IFERROR(VLOOKUP(D17,'📦 Productos'!B:E,4,0)*F17,0) -> 11634 | I17: =IFERROR(IF(ISNUMBER(G17),G17-H17,""),"") -> 3966 | J17: Tarjeta | K17: =IF(A17<>"",SUMIF($A$4:$A$107,A17,$G$4:$G$107),"")
B18: 46177 | C18: Frutos Secos | D18: Castaña de Cajú 1kg | E18: =IFERROR(VLOOKUP(D18,'📦 Productos'!B:F,5,0),"") -> 19900 | F18: 0.125 | G18: =IFERROR(IF(E18*F18>0,E18*F18,""),"") -> 2487.5 | H18: =IFERROR(VLOOKUP(D18,'📦 Productos'!B:E,4,0)*F18,0) -> 1687.5 | I18: =IFERROR(IF(ISNUMBER(G18),G18-H18,""),"") -> 800 | J18: Tarjeta | K18: =IF(A18<>"",SUMIF($A$4:$A$107,A18,$G$4:$G$107),"")
B19: 46177 | C19: Huevos | D19: Huevo Extra 30u | E19: =IFERROR(VLOOKUP(D19,'📦 Productos'!B:F,5,0),"") -> 8550 | F19: 1 | G19: =IFERROR(IF(E19*F19>0,E19*F19,""),"") -> 8550 | H19: =IFERROR(VLOOKUP(D19,'📦 Productos'!B:E,4,0)*F19,0) -> 6317 | I19: =IFERROR(IF(ISNUMBER(G19),G19-H19,""),"") -> 2233 | J19: Tarjeta | K19: =IF(A19<>"",SUMIF($A$4:$A$107,A19,$G$4:$G$107),"")
B20: 46177 | C20: Quesos | D20: Laminado 470g | E20: =IFERROR(VLOOKUP(D20,'📦 Productos'!B:F,5,0),"") -> 6500 | F20: 1 | G20: =IFERROR(IF(E20*F20>0,E20*F20,""),"") -> 6500 | H20: =IFERROR(VLOOKUP(D20,'📦 Productos'!B:E,4,0)*F20,0) -> 4701 | I20: =IFERROR(IF(ISNUMBER(G20),G20-H20,""),"") -> 1799 | J20: Tarjeta | K20: =IF(A20<>"",SUMIF($A$4:$A$107,A20,$G$4:$G$107),"")
B21: 46177 | C21: Quesos | D21: miel | E21: 7500 | F21: 1 | G21: =IFERROR(IF(E21*F21>0,E21*F21,""),"") -> 7500 | H21: =IFERROR(VLOOKUP(D21,'📦 Productos'!B:E,4,0)*F21,0) -> 0 | I21: =IFERROR(IF(ISNUMBER(G21),G21-H21,""),"") -> 7500 | J21: Tarjeta | K21: =IF(A21<>"",SUMIF($A$4:$A$107,A21,$G$4:$G$107),"")
B22: 46177 | C22: Frutos Secos | D22: Nueces 500g | E22: =IFERROR(VLOOKUP(D22,'📦 Productos'!B:F,5,0),"") -> 6800 | F22: 0.3 | G22: =IFERROR(IF(E22*F22>0,E22*F22,""),"") -> 2040 | H22: =IFERROR(VLOOKUP(D22,'📦 Productos'!B:E,4,0)*F22,0) -> 1270.5 | I22: =IFERROR(IF(ISNUMBER(G22),G22-H22,""),"") -> 769.5 | J22: Tarjeta | K22: =IF(A22<>"",SUMIF($A$4:$A$107,A22,$G$4:$G$107),"")
B23: 46177 | C23: Huevos | D23: Huevo Extra 180u | E23: =IFERROR(VLOOKUP(D23,'📦 Productos'!B:F,5,0),"") -> 49000 | F23: 1 | G23: =IFERROR(IF(E23*F23>0,E23*F23,""),"") -> 49000 | H23: =IFERROR(VLOOKUP(D23,'📦 Productos'!B:E,4,0)*F23,0) -> 37900 | I23: =IFERROR(IF(ISNUMBER(G23),G23-H23,""),"") -> 11100 | J23: Tarjeta | K23: =IF(A23<>"",SUMIF($A$4:$A$107,A23,$G$4:$G$107),"")
B24: 46177 | D24: palta | E24: 4500 | F24: 1 | G24: =IFERROR(IF(E24*F24>0,E24*F24,""),"") -> 4500 | H24: =IFERROR(VLOOKUP(D24,'📦 Productos'!B:E,4,0)*F24,0) -> 0 | I24: =IFERROR(IF(ISNUMBER(G24),G24-H24,""),"") -> 4500 | J24: Tarjeta | K24: =IF(A24<>"",SUMIF($A$4:$A$107,A24,$G$4:$G$107),"")
B25: 46177 | C25: Frutos Secos | D25: Maní sin Sal 500g | E25: =IFERROR(VLOOKUP(D25,'📦 Productos'!B:F,5,0),"") -> 2500 | F25: 1 | G25: =IFERROR(IF(E25*F25>0,E25*F25,""),"") -> 2500 | H25: =IFERROR(VLOOKUP(D25,'📦 Productos'!B:E,4,0)*F25,0) -> 1705 | I25: =IFERROR(IF(ISNUMBER(G25),G25-H25,""),"") -> 795 | J25: Tarjeta | K25: =IF(A25<>"",SUMIF($A$4:$A$107,A25,$G$4:$G$107),"")
B26: 46177 | C26: Huevos | D26: Huevo Extra 6u | E26: =IFERROR(VLOOKUP(D26,'📦 Productos'!B:F,5,0),"") -> 2140 | F26: 1 | G26: =IFERROR(IF(E26*F26>0,E26*F26,""),"") -> 2140 | H26: =IFERROR(VLOOKUP(D26,'📦 Productos'!B:E,4,0)*F26,0) -> 1263 | I26: =IFERROR(IF(ISNUMBER(G26),G26-H26,""),"") -> 877 | J26: Tarjeta | K26: =IF(A26<>"",SUMIF($A$4:$A$107,A26,$G$4:$G$107),"")
A27: 1 | B27: 46178 | C27: Mantequillas | D27: Mantequilla futurocoop | E27: =IFERROR(VLOOKUP(D27,'📦 Productos'!B:F,5,0),"") -> 2900 | F27: 1 | G27: =IFERROR(IF(E27*F27>0,E27*F27,""),"") -> 2900 | H27: =IFERROR(VLOOKUP(D27,'📦 Productos'!B:E,4,0)*F27,0) -> 2198.52 | I27: =IFERROR(IF(ISNUMBER(G27),G27-H27,""),"") -> 701.48 | J27: Tarjeta | K27: =IF(A27<>"",SUMIF($A$4:$A$107,A27,$G$4:$G$107),"") -> 2900
A28: 2 | B28: 46178 | C28: Quesos | D28: Laminado 470g | E28: =IFERROR(VLOOKUP(D28,'📦 Productos'!B:F,5,0),"") -> 6500 | F28: 1 | G28: =IFERROR(IF(E28*F28>0,E28*F28,""),"") -> 6500 | H28: =IFERROR(VLOOKUP(D28,'📦 Productos'!B:E,4,0)*F28,0) -> 4701 | I28: =IFERROR(IF(ISNUMBER(G28),G28-H28,""),"") -> 1799 | J28: Tarjeta | K28: =IF(A28<>"",SUMIF($A$4:$A$107,A28,$G$4:$G$107),"") -> 13200
A29: 2 | B29: 46178 | C29: Mermeladas | D29: 0% Frutos del bosque | E29: =IFERROR(VLOOKUP(D29,'📦 Productos'!B:F,5,0),"") -> 3500 | F29: 1 | G29: =IFERROR(IF(E29*F29>0,E29*F29,""),"") -> 3500 | H29: =IFERROR(VLOOKUP(D29,'📦 Productos'!B:E,4,0)*F29,0) -> 2023 | I29: =IFERROR(IF(ISNUMBER(G29),G29-H29,""),"") -> 1477 | J29: Tarjeta | K29: =IF(A29<>"",SUMIF($A$4:$A$107,A29,$G$4:$G$107),"") -> 13200
A30: 2 | B30: 46178 | C30: Mantequillas | D30: Mantequilla Lanalhue | E30: =IFERROR(VLOOKUP(D30,'📦 Productos'!B:F,5,0),"") -> 3200 | F30: 1 | G30: =IFERROR(IF(E30*F30>0,E30*F30,""),"") -> 3200 | H30: =IFERROR(VLOOKUP(D30,'📦 Productos'!B:E,4,0)*F30,0) -> 2166 | I30: =IFERROR(IF(ISNUMBER(G30),G30-H30,""),"") -> 1034 | J30: Tarjeta | K30: =IF(A30<>"",SUMIF($A$4:$A$107,A30,$G$4:$G$107),"") -> 13200
A31: 3 | B31: 46178 | C31: Aceitunas | D31: (500g) Aceituna Amarga | E31: =IFERROR(VLOOKUP(D31,'📦 Productos'!B:F,5,0),"") -> 4800 | F31: 1 | G31: =IFERROR(IF(E31*F31>0,E31*F31,""),"") -> 4800 | H31: =IFERROR(VLOOKUP(D31,'📦 Productos'!B:E,4,0)*F31,0) -> 3100 | I31: =IFERROR(IF(ISNUMBER(G31),G31-H31,""),"") -> 1700 | J31: Tarjeta | K31: =IF(A31<>"",SUMIF($A$4:$A$107,A31,$G$4:$G$107),"") -> 4800
A32: 4 | B32: 46178 | C32: QuesoCabra | D32: Oregano 200g | E32: =IFERROR(VLOOKUP(D32,'📦 Productos'!B:F,5,0),"") -> 5500 | F32: 1 | G32: =IFERROR(IF(E32*F32>0,E32*F32,""),"") -> 5500 | H32: =IFERROR(VLOOKUP(D32,'📦 Productos'!B:E,4,0)*F32,0) -> 3891 | I32: =IFERROR(IF(ISNUMBER(G32),G32-H32,""),"") -> 1609 | J32: Tarjeta | K32: =IF(A32<>"",SUMIF($A$4:$A$107,A32,$G$4:$G$107),"") -> 5500
A33: 5 | B33: 46178 | C33: Frutos Secos | D33: Mix Regodión 1kg | E33: 9200 | F33: 0.3 | G33: =IFERROR(IF(E33*F33>0,E33*F33,""),"") -> 2760 | H33: =IFERROR(VLOOKUP(D33,'📦 Productos'!B:E,4,0)*F33,0) -> 1740 | I33: =IFERROR(IF(ISNUMBER(G33),G33-H33,""),"") -> 1020 | J33: Tarjeta | K33: =IF(A33<>"",SUMIF($A$4:$A$107,A33,$G$4:$G$107),"") -> 2760
A34: 6 | B34: 46178 | C34: Huevos | D34: Huevo Extra 30u | E34: =IFERROR(VLOOKUP(D34,'📦 Productos'!B:F,5,0),"") -> 8550 | F34: 1 | G34: =IFERROR(IF(E34*F34>0,E34*F34,""),"") -> 8550 | H34: =IFERROR(VLOOKUP(D34,'📦 Productos'!B:E,4,0)*F34,0) -> 6317 | I34: =IFERROR(IF(ISNUMBER(G34),G34-H34,""),"") -> 2233 | J34: Tarjeta | K34: =IF(A34<>"",SUMIF($A$4:$A$107,A34,$G$4:$G$107),"") -> 8550
A35: 7 | B35: 46178 | C35: Frutos Secos | D35: Castaña de Cajú 100g | E35: =IFERROR(VLOOKUP(D35,'📦 Productos'!B:F,5,0),"") -> 2400 | F35: 1 | G35: =IFERROR(IF(E35*F35>0,E35*F35,""),"") -> 2400 | H35: =IFERROR(VLOOKUP(D35,'📦 Productos'!B:E,4,0)*F35,0) -> 1350 | I35: =IFERROR(IF(ISNUMBER(G35),G35-H35,""),"") -> 1050 | J35: Tarjeta | K35: =IF(A35<>"",SUMIF($A$4:$A$107,A35,$G$4:$G$107),"") -> 7400
A36: 7 | B36: 46178 | C36: Quesos | D36: Ahumado 200g | E36: =IFERROR(VLOOKUP(D36,'📦 Productos'!B:F,5,0),"") -> 5000 | F36: 1 | G36: =IFERROR(IF(E36*F36>0,E36*F36,""),"") -> 5000 | H36: =IFERROR(VLOOKUP(D36,'📦 Productos'!B:E,4,0)*F36,0) -> 2499 | I36: =IFERROR(IF(ISNUMBER(G36),G36-H36,""),"") -> 2501 | J36: Tarjeta | K36: =IF(A36<>"",SUMIF($A$4:$A$107,A36,$G$4:$G$107),"") -> 7400
A37: 8 | B37: 46178 | C37: Huevos | D37: Huevo Primera 30u | E37: =IFERROR(VLOOKUP(D37,'📦 Productos'!B:F,5,0),"") -> 7800 | F37: 1 | G37: =IFERROR(IF(E37*F37>0,E37*F37,""),"") -> 7800 | H37: =IFERROR(VLOOKUP(D37,'📦 Productos'!B:E,4,0)*F37,0) -> 5817 | I37: =IFERROR(IF(ISNUMBER(G37),G37-H37,""),"") -> 1983 | J37: Tarjeta | K37: =IF(A37<>"",SUMIF($A$4:$A$107,A37,$G$4:$G$107),"") -> 7800
A38: 9 | B38: 46178 | C38: Huevos | D38: Huevo Extra 30u | E38: =IFERROR(VLOOKUP(D38,'📦 Productos'!B:F,5,0),"") -> 8550 | F38: 1 | G38: =IFERROR(IF(E38*F38>0,E38*F38,""),"") -> 8550 | H38: =IFERROR(VLOOKUP(D38,'📦 Productos'!B:E,4,0)*F38,0) -> 6317 | I38: =IFERROR(IF(ISNUMBER(G38),G38-H38,""),"") -> 2233 | J38: Tarjeta | K38: =IF(A38<>"",SUMIF($A$4:$A$107,A38,$G$4:$G$107),"") -> 16294
A39: 9 | B39: 46178 | C39: Frutos Secos | D39: Nueces 1kg | E39: =IFERROR(VLOOKUP(D39,'📦 Productos'!B:F,5,0),"") -> 13200 | F39: 0.17 | G39: =IFERROR(IF(E39*F39>0,E39*F39,""),"") -> 2244 | H39: =IFERROR(VLOOKUP(D39,'📦 Productos'!B:E,4,0)*F39,0) -> 1439.9 | I39: =IFERROR(IF(ISNUMBER(G39),G39-H39,""),"") -> 804.1 | J39: Tarjeta | K39: =IF(A39<>"",SUMIF($A$4:$A$107,A39,$G$4:$G$107),"") -> 16294
A40: 9 | B40: 46178 | C40: QuesoCabra | D40: Natural200g | E40: =IFERROR(VLOOKUP(D40,'📦 Productos'!B:F,5,0),"") -> 5500 | F40: 1 | G40: =IFERROR(IF(E40*F40>0,E40*F40,""),"") -> 5500 | H40: =IFERROR(VLOOKUP(D40,'📦 Productos'!B:E,4,0)*F40,0) -> 3831.8 | I40: =IFERROR(IF(ISNUMBER(G40),G40-H40,""),"") -> 1668.2 | J40: Tarjeta | K40: =IF(A40<>"",SUMIF($A$4:$A$107,A40,$G$4:$G$107),"") -> 16294
...

Sheet 📊 Resumen Mensual
A1: 📊 RESUMEN MENSUAL DE VENTAS Y GANANCIAS
A3: VENTAS POR CATEGORÍA
A4: Categoría | B4: Unidades | C4: Ingresos ($) | D4: Costos ($) | E4: Ganancia ($) | F4: Margen (%) | G4: % Total | H4: Meta ($)
A5: Aceitunas | B5: =SUMIF('🛒 Ventas del Día'!C$4:C$107,A5,'🛒 Ventas del Día'!F$4:F$107) -> 2 | C5: =SUMIF('🛒 Ventas del Día'!C$4:C$107,A5,'🛒 Ventas del Día'!G$4:G$107) -> 12800 | D5: =IFERROR(SUMIF('🛒 Ventas del Día'!C$4:C$107,A5,'🛒 Ventas del Día'!H$4:H$107),0) -> 8000 | E5: =C5-D5 -> 4800 | F5: =IF(C5>0,(C5-D5)/C5,0) -> 0.375 | G5: =IF(C$13>0,C5/C$13,0) -> 0.035330178 | H5: 0
A6: Embutidos | B6: =SUMIF('🛒 Ventas del Día'!C$4:C$107,A6,'🛒 Ventas del Día'!F$4:F$107) -> 0 | C6: =SUMIF('🛒 Ventas del Día'!C$4:C$107,A6,'🛒 Ventas del Día'!G$4:G$107) -> 0 | D6: =IFERROR(SUMIF('🛒 Ventas del Día'!C$4:C$107,A6,'🛒 Ventas del Día'!H$4:H$107),0) -> 0 | E6: =C6-D6 -> 0 | F6: =IF(C6>0,(C6-D6)/C6,0) -> 0 | G6: =IF(C$13>0,C6/C$13,0) -> 0 | H6: 0
A7: Frutos Secos | B7: =SUMIF('🛒 Ventas del Día'!C$4:C$107,A7,'🛒 Ventas del Día'!F$4:F$107) -> 9.045 | C7: =SUMIF('🛒 Ventas del Día'!C$4:C$107,A7,'🛒 Ventas del Día'!G$4:G$107) -> 29396.5 | D7: =IFERROR(SUMIF('🛒 Ventas del Día'!C$4:C$107,A7,'🛒 Ventas del Día'!H$4:H$107),0) -> 18905.9 | E7: =C7-D7 -> 10490.6 | F7: =IF(C7>0,(C7-D7)/C7,0) -> 0.35686561 | G7: =IF(C$13>0,C7/C$13,0) -> 0.081139343 | H7: 0
A8: Huevos | B8: =SUMIF('🛒 Ventas del Día'!C$4:C$107,A8,'🛒 Ventas del Día'!F$4:F$107) -> 23 | C8: =SUMIF('🛒 Ventas del Día'!C$4:C$107,A8,'🛒 Ventas del Día'!G$4:G$107) -> 262000 | D8: =IFERROR(SUMIF('🛒 Ventas del Día'!C$4:C$107,A8,'🛒 Ventas del Día'!H$4:H$107),0) -> 199091 | E8: =C8-D8 -> 62909 | F8: =IF(C8>0,(C8-D8)/C8,0) -> 0.24011069 | G8: =IF(C$13>0,C8/C$13,0) -> 0.72316459 | H8: 0
A9: Mantequillas | B9: =SUMIF('🛒 Ventas del Día'!C$4:C$107,A9,'🛒 Ventas del Día'!F$4:F$107) -> 2 | C9: =SUMIF('🛒 Ventas del Día'!C$4:C$107,A9,'🛒 Ventas del Día'!G$4:G$107) -> 6100 | D9: =IFERROR(SUMIF('🛒 Ventas del Día'!C$4:C$107,A9,'🛒 Ventas del Día'!H$4:H$107),0) -> 4364.52 | E9: =C9-D9 -> 1735.48 | F9: =IF(C9>0,(C9-D9)/C9,0) -> 0.28450492 | G9: =IF(C$13>0,C9/C$13,0) -> 0.016837038 | H9: 0
A10: Mermeladas | B10: =SUMIF('🛒 Ventas del Día'!C$4:C$107,A10,'🛒 Ventas del Día'!F$4:F$107) -> 1 | C10: =SUMIF('🛒 Ventas del Día'!C$4:C$107,A10,'🛒 Ventas del Día'!G$4:G$107) -> 3500 | D10: =IFERROR(SUMIF('🛒 Ventas del Día'!C$4:C$107,A10,'🛒 Ventas del Día'!H$4:H$107),0) -> 2023 | E10: =C10-D10 -> 1477 | F10: =IF(C10>0,(C10-D10)/C10,0) -> 0.422 | G10: =IF(C$13>0,C10/C$13,0) -> 0.0096605957 | H10: 0
A11: QuesoCabra | B11: =SUMIF('🛒 Ventas del Día'!C$4:C$107,A11,'🛒 Ventas del Día'!F$4:F$107) -> 2 | C11: =SUMIF('🛒 Ventas del Día'!C$4:C$107,A11,'🛒 Ventas del Día'!G$4:G$107) -> 11000 | D11: =IFERROR(SUMIF('🛒 Ventas del Día'!C$4:C$107,A11,'🛒 Ventas del Día'!H$4:H$107),0) -> 7722.8 | E11: =C11-D11 -> 3277.2 | F11: =IF(C11>0,(C11-D11)/C11,0) -> 0.29792727 | G11: =IF(C$13>0,C11/C$13,0) -> 0.030361872 | H11: 0
A12: Quesos | B12: =SUMIF('🛒 Ventas del Día'!C$4:C$107,A12,'🛒 Ventas del Día'!F$4:F$107) -> 6 | C12: =SUMIF('🛒 Ventas del Día'!C$4:C$107,A12,'🛒 Ventas del Día'!G$4:G$107) -> 37500 | D12: =IFERROR(SUMIF('🛒 Ventas del Día'!C$4:C$107,A12,'🛒 Ventas del Día'!H$4:H$107),0) -> 18918 | E12: =C12-D12 -> 18582 | F12: =IF(C12>0,(C12-D12)/C12,0) -> 0.49552 | G12: =IF(C$13>0,C12/C$13,0) -> 0.10350638 | H12: 0
A13: TOTAL | B13: =SUM(B5:B12) -> 45.045 | C13: =SUM(C5:C12) -> 362296.5 | D13: =SUM(D5:D12) -> 259025.22 | E13: =C13-D13 -> 103271.28 | F13: =IF(C13>0,(C13-D13)/C13,0) -> 0.28504631 | H13: =SUM(H5:H12) -> 0
A15: VENTAS DIARIAS DEL MES
A16: Fecha | B16: Trans. | C16: Ingresos ($) | D16: Costos ($) | E16: Ganancia ($) | F16: Margen (%) | G16: Efectivo ($) | H16: Tarjeta ($) | I16: Nº Boletas | J16: Ticket Prom ($)
A17: 46174 | B17: =COUNTIF('🛒 Ventas del Día'!B$4:B$107,A17) -> 0 | C17: =SUMIF('🛒 Ventas del Día'!B$4:B$107,A17,'🛒 Ventas del Día'!G$4:G$107) -> 0 | D17: =IFERROR(SUMIF('🛒 Ventas del Día'!B$4:B$107,A17,'🛒 Ventas del Día'!H$4:H$107),0) -> 0 | E17: =C17-D17 -> 0 | F17: =IF(C17>0,(C17-D17)/C17,0) -> 0 | G17: =SUMIFS('🛒 Ventas del Día'!G$4:G$107,'🛒 Ventas del Día'!B$4:B$107,A17,'🛒 Ventas del Día'!J$4:J$107,"Efectivo") -> 0 | H17: =SUMIFS('🛒 Ventas del Día'!G$4:G$107,'🛒 Ventas del Día'!B$4:B$107,A17,'🛒 Ventas del Día'!J$4:J$107,"Tarjeta") -> 0 | I17: =IFERROR(SUMPRODUCT(('🛒 Ventas del Día'!$B$4:$B$107=A17)*('🛒 Ventas del Día'!$A$4:$A$107<>"")/COUNTIF('🛒 Ventas del Día'!$A$4:$A$107,'🛒 Ventas del Día'!$A$4:$A$107&"")),0) -> 0 | J17: =IFERROR(C17/I17,0) -> 0
A18: 46175 | B18: =COUNTIF('🛒 Ventas del Día'!B$4:B$107,A18) -> 0 | C18: =SUMIF('🛒 Ventas del Día'!B$4:B$107,A18,'🛒 Ventas del Día'!G$4:G$107) -> 0 | D18: =IFERROR(SUMIF('🛒 Ventas del Día'!B$4:B$107,A18,'🛒 Ventas del Día'!H$4:H$107),0) -> 0 | E18: =C18-D18 -> 0 | F18: =IF(C18>0,(C18-D18)/C18,0) -> 0 | G18: =SUMIFS('🛒 Ventas del Día'!G$4:G$107,'🛒 Ventas del Día'!B$4:B$107,A18,'🛒 Ventas del Día'!J$4:J$107,"Efectivo") -> 0 | H18: =SUMIFS('🛒 Ventas del Día'!G$4:G$107,'🛒 Ventas del Día'!B$4:B$107,A18,'🛒 Ventas del Día'!J$4:J$107,"Tarjeta") -> 0 | I18: =IFERROR(SUMPRODUCT(('🛒 Ventas del Día'!$B$4:$B$107=A18)*('🛒 Ventas del Día'!$A$4:$A$107<>"")/COUNTIF('🛒 Ventas del Día'!$A$4:$A$107,'🛒 Ventas del Día'!$A$4:$A$107&"")),0) -> 0 | J18: =IFERROR(C18/I18,0) -> 0
A19: 46176 | B19: =COUNTIF('🛒 Ventas del Día'!B$4:B$107,A19) -> 9 | C19: =SUMIF('🛒 Ventas del Día'!B$4:B$107,A19,'🛒 Ventas del Día'!G$4:G$107) -> 69050 | D19: =IFERROR(SUMIF('🛒 Ventas del Día'!B$4:B$107,A19,'🛒 Ventas del Día'!H$4:H$107),0) -> 51538 | E19: =C19-D19 -> 17512 | F19: =IF(C19>0,(C19-D19)/C19,0) -> 0.25361332 | G19: =SUMIFS('🛒 Ventas del Día'!G$4:G$107,'🛒 Ventas del Día'!B$4:B$107,A19,'🛒 Ventas del Día'!J$4:J$107,"Efectivo") -> 0 | H19: =SUMIFS('🛒 Ventas del Día'!G$4:G$107,'🛒 Ventas del Día'!B$4:B$107,A19,'🛒 Ventas del Día'!J$4:J$107,"Tarjeta") -> 0 | I19: =IFERROR(SUMPRODUCT(('🛒 Ventas del Día'!$B$4:$B$107=A19)*('🛒 Ventas del Día'!$A$4:$A$107<>"")/COUNTIF('🛒 Ventas del Día'!$A$4:$A$107,'🛒 Ventas del Día'!$A$4:$A$107&"")),0) -> 0 | J19: =IFERROR(C19/I19,0) -> 0
A20: 46177 | B20: =COUNTIF('🛒 Ventas del Día'!B$4:B$107,A20) -> 14 | C20: =SUMIF('🛒 Ventas del Día'!B$4:B$107,A20,'🛒 Ventas del Día'!G$4:G$107) -> 123117.5 | D20: =IFERROR(SUMIF('🛒 Ventas del Día'!B$4:B$107,A20,'🛒 Ventas del Día'!H$4:H$107),0) -> 82169 | E20: =C20-D20 -> 40948.5 | F20: =IF(C20>0,(C20-D20)/C20,0) -> 0.33259691 | G20: =SUMIFS('🛒 Ventas del Día'!G$4:G$107,'🛒 Ventas del Día'!B$4:B$107,A20,'🛒 Ventas del Día'!J$4:J$107,"Efectivo") -> 0 | H20: =SUMIFS('🛒 Ventas del Día'!G$4:G$107,'🛒 Ventas del Día'!B$4:B$107,A20,'🛒 Ventas del Día'!J$4:J$107,"Tarjeta") -> 121617.5 | I20: =IFERROR(SUMPRODUCT(('🛒 Ventas del Día'!$B$4:$B$107=A20)*('🛒 Ventas del Día'!$A$4:$A$107<>"")/COUNTIF('🛒 Ventas del Día'!$A$4:$A$107,'🛒 Ventas del Día'!$A$4:$A$107&"")),0) -> 0 | J20: =IFERROR(C20/I20,0) -> 0
A21: 46178 | B21: =COUNTIF('🛒 Ventas del Día'!B$4:B$107,A21) -> 24 | C21: =SUMIF('🛒 Ventas del Día'!B$4:B$107,A21,'🛒 Ventas del Día'!G$4:G$107) -> 174629 | D21: =IFERROR(SUMIF('🛒 Ventas del Día'!B$4:B$107,A21,'🛒 Ventas del Día'!H$4:H$107),0) -> 125318.22 | E21: =C21-D21 -> 49310.78 | F21: =IF(C21>0,(C21-D21)/C21,0) -> 0.28237452 | G21: =SUMIFS('🛒 Ventas del Día'!G$4:G$107,'🛒 Ventas del Día'!B$4:B$107,A21,'🛒 Ventas del Día'!J$4:J$107,"Efectivo") -> 25915 | H21: =SUMIFS('🛒 Ventas del Día'!G$4:G$107,'🛒 Ventas del Día'!B$4:B$107,A21,'🛒 Ventas del Día'!J$4:J$107,"Tarjeta") -> 99714 | I21: =IFERROR(SUMPRODUCT(('🛒 Ventas del Día'!$B$4:$B$107=A21)*('🛒 Ventas del Día'!$A$4:$A$107<>"")/COUNTIF('🛒 Ventas del Día'!$A$4:$A$107,'🛒 Ventas del Día'!$A$4:$A$107&"")),0) -> 17 | J21: =IFERROR(C21/I21,0) -> 10272.294
A22: 46179 | B22: =COUNTIF('🛒 Ventas del Día'!B$4:B$107,A22) -> 0 | C22: =SUMIF('🛒 Ventas del Día'!B$4:B$107,A22,'🛒 Ventas del Día'!G$4:G$107) -> 0 | D22: =IFERROR(SUMIF('🛒 Ventas del Día'!B$4:B$107,A22,'🛒 Ventas del Día'!H$4:H$107),0) -> 0 | E22: =C22-D22 -> 0 | F22: =IF(C22>0,(C22-D22)/C22,0) -> 0 | G22: =SUMIFS('🛒 Ventas del Día'!G$4:G$107,'🛒 Ventas del Día'!B$4:B$107,A22,'🛒 Ventas del Día'!J$4:J$107,"Efectivo") -> 0 | H22: =SUMIFS('🛒 Ventas del Día'!G$4:G$107,'🛒 Ventas del Día'!B$4:B$107,A22,'🛒 Ventas del Día'!J$4:J$107,"Tarjeta") -> 0 | I22: =IFERROR(SUMPRODUCT(('🛒 Ventas del Día'!$B$4:$B$107=A22)*('🛒 Ventas del Día'!$A$4:$A$107<>"")/COUNTIF('🛒 Ventas del Día'!$A$4:$A$107,'🛒 Ventas del Día'!$A$4:$A$107&"")),0) -> 0 | J22: =IFERROR(C22/I22,0) -> 0
A23: 46180 | B23: =COUNTIF('🛒 Ventas del Día'!B$4:B$107,A23) -> 0 | C23: =SUMIF('🛒 Ventas del Día'!B$4:B$107,A23,'🛒 Ventas del Día'!G$4:G$107) -> 0 | D23: =IFERROR(SUMIF('🛒 Ventas del Día'!B$4:B$107,A23,'🛒 Ventas del Día'!H$4:H$107),0) -> 0 | E23: =C23-D23 -> 0 | F23: =IF(C23>0,(C23-D23)/C23,0) -> 0 | G23: =SUMIFS('🛒 Ventas del Día'!G$4:G$107,'🛒 Ventas del Día'!B$4:B$107,A23,'🛒 Ventas del Día'!J$4:J$107,"Efectivo") -> 0 | H23: =SUMIFS('🛒 Ventas del Día'!G$4:G$107,'🛒 Ventas del Día'!B$4:B$107,A23,'🛒 Ventas del Día'!J$4:J$107,"Tarjeta") -> 0 | I23: =IFERROR(SUMPRODUCT(('🛒 Ventas del Día'!$B$4:$B$107=A23)*('🛒 Ventas del Día'!$A$4:$A$107<>"")/COUNTIF('🛒 Ventas del Día'!$A$4:$A$107,'🛒 Ventas del Día'!$A$4:$A$107&"")),0) -> 0 | J23: =IFERROR(C23/I23,0) -> 0
A24: 46181 | B24: =COUNTIF('🛒 Ventas del Día'!B$4:B$107,A24) -> 0 | C24: =SUMIF('🛒 Ventas del Día'!B$4:B$107,A24,'🛒 Ventas del Día'!G$4:G$107) -> 0 | D24: =IFERROR(SUMIF('🛒 Ventas del Día'!B$4:B$107,A24,'🛒 Ventas del Día'!H$4:H$107),0) -> 0 | E24: =C24-D24 -> 0 | F24: =IF(C24>0,(C24-D24)/C24,0) -> 0 | G24: =SUMIFS('🛒 Ventas del Día'!G$4:G$107,'🛒 Ventas del Día'!B$4:B$107,A24,'🛒 Ventas del Día'!J$4:J$107,"Efectivo") -> 0 | H24: =SUMIFS('🛒 Ventas del Día'!G$4:G$107,'🛒 Ventas del Día'!B$4:B$107,A24,'🛒 Ventas del Día'!J$4:J$107,"Tarjeta") -> 0 | I24: =IFERROR(SUMPRODUCT(('🛒 Ventas del Día'!$B$4:$B$107=A24)*('🛒 Ventas del Día'!$A$4:$A$107<>"")/COUNTIF('🛒 Ventas del Día'!$A$4:$A$107,'🛒 Ventas del Día'!$A$4:$A$107&"")),0) -> 0 | J24: =IFERROR(C24/I24,0) -> 0
A25: 46182 | B25: =COUNTIF('🛒 Ventas del Día'!B$4:B$107,A25) -> 0 | C25: =SUMIF('🛒 Ventas del Día'!B$4:B$107,A25,'🛒 Ventas del Día'!G$4:G$107) -> 0 | D25: =IFERROR(SUMIF('🛒 Ventas del Día'!B$4:B$107,A25,'🛒 Ventas del Día'!H$4:H$107),0) -> 0 | E25: =C25-D25 -> 0 | F25: =IF(C25>0,(C25-D25)/C25,0) -> 0 | G25: =SUMIFS('🛒 Ventas del Día'!G$4:G$107,'🛒 Ventas del Día'!B$4:B$107,A25,'🛒 Ventas del Día'!J$4:J$107,"Efectivo") -> 0 | H25: =SUMIFS('🛒 Ventas del Día'!G$4:G$107,'🛒 Ventas del Día'!B$4:B$107,A25,'🛒 Ventas del Día'!J$4:J$107,"Tarjeta") -> 0 | I25: =IFERROR(SUMPRODUCT(('🛒 Ventas del Día'!$B$4:$B$107=A25)*('🛒 Ventas del Día'!$A$4:$A$107<>"")/COUNTIF('🛒 Ventas del Día'!$A$4:$A$107,'🛒 Ventas del Día'!$A$4:$A$107&"")),0) -> 0 | J25: =IFERROR(C25/I25,0) -> 0
A26: 46183 | B26: =COUNTIF('🛒 Ventas del Día'!B$4:B$107,A26) -> 0 | C26: =SUMIF('🛒 Ventas del Día'!B$4:B$107,A26,'🛒 Ventas del Día'!G$4:G$107) -> 0 | D26: =IFERROR(SUMIF('🛒 Ventas del Día'!B$4:B$107,A26,'🛒 Ventas del Día'!H$4:H$107),0) -> 0 | E26: =C26-D26 -> 0 | F26: =IF(C26>0,(C26-D26)/C26,0) -> 0 | G26: =SUMIFS('🛒 Ventas del Día'!G$4:G$107,'🛒 Ventas del Día'!B$4:B$107,A26,'🛒 Ventas del Día'!J$4:J$107,"Efectivo") -> 0 | H26: =SUMIFS('🛒 Ventas del Día'!G$4:G$107,'🛒 Ventas del Día'!B$4:B$107,A26,'🛒 Ventas del Día'!J$4:J$107,"Tarjeta") -> 0 | I26: =IFERROR(SUMPRODUCT(('🛒 Ventas del Día'!$B$4:$B$107=A26)*('🛒 Ventas del Día'!$A$4:$A$107<>"")/COUNTIF('🛒 Ventas del Día'!$A$4:$A$107,'🛒 Ventas del Día'!$A$4:$A$107&"")),0) -> 0 | J26: =IFERROR(C26/I26,0) -> 0
A27: 46184 | B27: =COUNTIF('🛒 Ventas del Día'!B$4:B$107,A27) -> 0 | C27: =SUMIF('🛒 Ventas del Día'!B$4:B$107,A27,'🛒 Ventas del Día'!G$4:G$107) -> 0 | D27: =IFERROR(SUMIF('🛒 Ventas del Día'!B$4:B$107,A27,'🛒 Ventas del Día'!H$4:H$107),0) -> 0 | E27: =C27-D27 -> 0 | F27: =IF(C27>0,(C27-D27)/C27,0) -> 0 | G27: =SUMIFS('🛒 Ventas del Día'!G$4:G$107,'🛒 Ventas del Día'!B$4:B$107,A27,'🛒 Ventas del Día'!J$4:J$107,"Efectivo") -> 0 | H27: =SUMIFS('🛒 Ventas del Día'!G$4:G$107,'🛒 Ventas del Día'!B$4:B$107,A27,'🛒 Ventas del Día'!J$4:J$107,"Tarjeta") -> 0 | I27: =IFERROR(SUMPRODUCT(('🛒 Ventas del Día'!$B$4:$B$107=A27)*('🛒 Ventas del Día'!$A$4:$A$107<>"")/COUNTIF('🛒 Ventas del Día'!$A$4:$A$107,'🛒 Ventas del Día'!$A$4:$A$107&"")),0) -> 0 | J27: =IFERROR(C27/I27,0) -> 0
A28: 46185 | B28: =COUNTIF('🛒 Ventas del Día'!B$4:B$107,A28) -> 0 | C28: =SUMIF('🛒 Ventas del Día'!B$4:B$107,A28,'🛒 Ventas del Día'!G$4:G$107) -> 0 | D28: =IFERROR(SUMIF('🛒 Ventas del Día'!B$4:B$107,A28,'🛒 Ventas del Día'!H$4:H$107),0) -> 0 | E28: =C28-D28 -> 0 | F28: =IF(C28>0,(C28-D28)/C28,0) -> 0 | G28: =SUMIFS('🛒 Ventas del Día'!G$4:G$107,'🛒 Ventas del Día'!B$4:B$107,A28,'🛒 Ventas del Día'!J$4:J$107,"Efectivo") -> 0 | H28: =SUMIFS('🛒 Ventas del Día'!G$4:G$107,'🛒 Ventas del Día'!B$4:B$107,A28,'🛒 Ventas del Día'!J$4:J$107,"Tarjeta") -> 0 | I28: =IFERROR(SUMPRODUCT(('🛒 Ventas del Día'!$B$4:$B$107=A28)*('🛒 Ventas del Día'!$A$4:$A$107<>"")/COUNTIF('🛒 Ventas del Día'!$A$4:$A$107,'🛒 Ventas del Día'!$A$4:$A$107&"")),0) -> 0 | J28: =IFERROR(C28/I28,0) -> 0
... A46: 46203 | B46: =COUNTIF('🛒 Ventas del Día'!B$4:B$107,A46) -> 0 | C46: =SUMIF('🛒 Ventas del Día'!B$4:B$107,A46,'🛒 Ventas del Día'!G$4:G$107) -> 0 | D46: =IFERROR(SUMIF('🛒 Ventas del Día'!B$4:B$107,A46,'🛒 Ventas del Día'!H$4:H$107),0) -> 0 | E46: =C46-D46 -> 0 | F46: =IF(C46>0,(C46-D46)/C46,0) -> 0 | G46: =SUMIFS('🛒 Ventas del Día'!G$4:G$107,'🛒 Ventas del Día'!B$4:B$107,A46,'🛒 Ventas del Día'!J$4:J$107,"Efectivo") -> 0 | H46: =SUMIFS('🛒 Ventas del Día'!G$4:G$107,'🛒 Ventas del Día'!B$4:B$107,A46,'🛒 Ventas del Día'!J$4:J$107,"Tarjeta") -> 0 | I46: =IFERROR(SUMPRODUCT(('🛒 Ventas del Día'!$B$4:$B$107=A46)*('🛒 Ventas del Día'!$A$4:$A$107<>"")/COUNTIF('🛒 Ventas del Día'!$A$4:$A$107,'🛒 Ventas del Día'!$A$4:$A$107&"")),0) -> 0 | J46: =IFERROR(C46/I46,0) -> 0
A47: TOTAL / PROMEDIO DEL MES | G47: =SUM(G17:G46) -> 25915 | H47: =SUM(H17:H46) -> 221331.5 | I47: =SUM(I17:I46) -> 17 | J47: =IFERROR(SUM(C17:C46)/I47,0) -> 21576.265
A49: 📊 RESUMEN DE CLIENTES Y TICKET PROMEDIO
A50: Indicador | B50: Valor
A51: Total Boletas (mes) | B51: =I47 -> 17
A52: Ticket Promedio (mes) | B52: =J47 -> 21576.265
A53: Ingresos Totales | B53: =SUM(C17:C46) -> 366796.5
A54: Ganancia Total | B54: =SUM(E17:E46) -> 107771.28
A55: Margen Promedio | B55: =IFERROR(SUM(E17:E46)/SUM(C17:C46),0) -> 0.29381763
A56: Ticket Máximo | B56: =IFERROR(MAX('🛒 Ventas del Día'!K$4:K$107),0) -> 49000
A57: Boletas promedio/día | B57: =IFERROR(AVERAGEIF(I17:I46,">0"),0) -> 17
A58: Ingresos promedio/día | B58: =IFERROR(AVERAGEIF(C17:C46,">0"),0) -> 122265.5
A59: Ganancia promedio/día | B59: =IFERROR(AVERAGEIF(E17:E46,">0"),0) -> 35923.76

Sheet 📦 Inventario
A1: 📦 CONTROL DE INVENTARIO Y STOCK
A3: 🥚 STOCK DE HUEVOS — Por Calibre
A4: Calibre | B4: Stock Inicial | C4: Vendido | D4: Stock Actual | E4: Stock Mín | F4: Estado
A5: Primera | B5: 0 | C5: =SUMIF('🛒 Ventas del Día'!D$4:D$107,"Huevo Primera 6u",'🛒 Ventas del Día'!F$4:F$107)*6+SUMIF('🛒 Ventas del Día'!D$4:D$107,"Huevo Primera 12u",'🛒 Ventas del Día'!F$4:F$107)*12+SUMIF('🛒 Ventas del Día'!D$4:D$107,"Huevo Primera 15u",'🛒 Ventas del Día'!F$4:F$107)*15+SUMIF('🛒 Ventas del Día'!D$4:D$107,"Huevo Primera 30u",'🛒 Ventas del Día'!F$4:F$107)*30+SUMIF('🛒 Ventas del Día'!D$4:D$107,"Huevo Primera 180u",'🛒 Ventas del Día'!F$4:F$107)*180 -> 156 | D5: =B5-C5 -> -156 | E5: 0 | F5: =IF(D5<=0,"❌ SIN STOCK",IF(D5<=E5,"⚠️ STOCK BAJO","✅ OK")) -> ❌ SIN STOCK
A6: Extra | B6: 0 | C6: =SUMIF('🛒 Ventas del Día'!D$4:D$107,"Huevo Extra 6u",'🛒 Ventas del Día'!F$4:F$107)*6+SUMIF('🛒 Ventas del Día'!D$4:D$107,"Huevo Extra 12u",'🛒 Ventas del Día'!F$4:F$107)*12+SUMIF('🛒 Ventas del Día'!D$4:D$107,"Huevo Extra 15u",'🛒 Ventas del Día'!F$4:F$107)*15+SUMIF('🛒 Ventas del Día'!D$4:D$107,"Huevo Extra 30u",'🛒 Ventas del Día'!F$4:F$107)*30+SUMIF('🛒 Ventas del Día'!D$4:D$107,"Huevo Extra 180u",'🛒 Ventas del Día'!F$4:F$107)*180 -> 648 | D6: =B6-C6 -> -648 | E6: 0 | F6: =IF(D6<=0,"❌ SIN STOCK",IF(D6<=E6,"⚠️ STOCK BAJO","✅ OK")) -> ❌ SIN STOCK
A7: Super | B7: 0 | C7: =SUMIF('🛒 Ventas del Día'!D$4:D$107,"Huevo Super 6u",'🛒 Ventas del Día'!F$4:F$107)*6+SUMIF('🛒 Ventas del Día'!D$4:D$107,"Huevo Super 12u",'🛒 Ventas del Día'!F$4:F$107)*12+SUMIF('🛒 Ventas del Día'!D$4:D$107,"Huevo Super 15u",'🛒 Ventas del Día'!F$4:F$107)*15+SUMIF('🛒 Ventas del Día'!D$4:D$107,"Huevo Super 30u",'🛒 Ventas del Día'!F$4:F$107)*30+SUMIF('🛒 Ventas del Día'!D$4:D$107,"Huevo Super 180u",'🛒 Ventas del Día'!F$4:F$107)*180 -> 120 | D7: =B7-C7 -> -120 | E7: 0 | F7: =IF(D7<=0,"❌ SIN STOCK",IF(D7<=E7,"⚠️ STOCK BAJO","✅ OK")) -> ❌ SIN STOCK
A8: Jumbo | B8: 0 | C8: =SUMIF('🛒 Ventas del Día'!D$4:D$107,"Huevo Jumbo 20u",'🛒 Ventas del Día'!F$4:F$107)*20+SUMIF('🛒 Ventas del Día'!D$4:D$107,"Huevo Jumbo 100u",'🛒 Ventas del Día'!F$4:F$107)*100 -> 0 | D8: =B8-C8 -> 0 | E8: 0 | F8: =IF(D8<=0,"❌ SIN STOCK",IF(D8<=E8,"⚠️ STOCK BAJO","✅ OK")) -> ❌ SIN STOCK
A10: 🌰 STOCK DE FRUTOS SECOS — Por Producto (Kg)
A11: Producto | B11: Stock Ini (kg) | C11: Vendido (kg) | D11: Stock Act (kg) | E11: Stock Mín | F11: Estado
A12: Almendras | B12: 0 | C12: =SUMIF('🛒 Ventas del Día'!D$4:D$107,"Almendras 100g",'🛒 Ventas del Día'!F$4:F$107)*0.1+SUMIF('🛒 Ventas del Día'!D$4:D$107,"Almendras 250g",'🛒 Ventas del Día'!F$4:F$107)*0.25+SUMIF('🛒 Ventas del Día'!D$4:D$107,"Almendras 500g",'🛒 Ventas del Día'!F$4:F$107)*0.5+SUMIF('🛒 Ventas del Día'!D$4:D$107,"Almendras 1kg",'🛒 Ventas del Día'!F$4:F$107)*1 -> 0.1 | D12: =B12-C12 -> -0.1 | E12: 0 | F12: =IF(D12<=0,"❌ SIN STOCK",IF(D12<=E12,"⚠️ STOCK BAJO","✅ OK")) -> ❌ SIN STOCK
A13: Castaña de Cajú | B13: 0 | C13: =SUMIF('🛒 Ventas del Día'!D$4:D$107,"Castaña de Cajú 100g",'🛒 Ventas del Día'!F$4:F$107)*0.1+SUMIF('🛒 Ventas del Día'!D$4:D$107,"Castaña de Cajú 250g",'🛒 Ventas del Día'!F$4:F$107)*0.25+SUMIF('🛒 Ventas del Día'!D$4:D$107,"Castaña de Cajú 500g",'🛒 Ventas del Día'!F$4:F$107)*0.5+SUMIF('🛒 Ventas del Día'!D$4:D$107,"Castaña de Cajú 1kg",'🛒 Ventas del Día'!F$4:F$107)*1 -> 0.375 | D13: =B13-C13 -> -0.375 | E13: 0 | F13: =IF(D13<=0,"❌ SIN STOCK",IF(D13<=E13,"⚠️ STOCK BAJO","✅ OK")) -> ❌ SIN STOCK
A14: Maní sin Sal | B14: 0 | C14: =SUMIF('🛒 Ventas del Día'!D$4:D$107,"Maní sin Sal 100g",'🛒 Ventas del Día'!F$4:F$107)*0.1+SUMIF('🛒 Ventas del Día'!D$4:D$107,"Maní sin Sal 250g",'🛒 Ventas del Día'!F$4:F$107)*0.25+SUMIF('🛒 Ventas del Día'!D$4:D$107,"Maní sin Sal 500g",'🛒 Ventas del Día'!F$4:F$107)*0.5+SUMIF('🛒 Ventas del Día'!D$4:D$107,"Maní sin Sal 1kg",'🛒 Ventas del Día'!F$4:F$107)*1 -> 1.6 | D14: =B14-C14 -> -1.6 | E14: 0 | F14: =IF(D14<=0,"❌ SIN STOCK",IF(D14<=E14,"⚠️ STOCK BAJO","✅ OK")) -> ❌ SIN STOCK
A15: Mix Regodión | B15: 0 | C15: =SUMIF('🛒 Ventas del Día'!D$4:D$107,"Mix Regodión 100g",'🛒 Ventas del Día'!F$4:F$107)*0.1+SUMIF('🛒 Ventas del Día'!D$4:D$107,"Mix Regodión 250g",'🛒 Ventas del Día'!F$4:F$107)*0.25+SUMIF('🛒 Ventas del Día'!D$4:D$107,"Mix Regodión 500g",'🛒 Ventas del Día'!F$4:F$107)*0.5+SUMIF('🛒 Ventas del Día'!D$4:D$107,"Mix Regodión 1kg",'🛒 Ventas del Día'!F$4:F$107)*1 -> 0.65 | D15: =B15-C15 -> -0.65 | E15: 0 | F15: =IF(D15<=0,"❌ SIN STOCK",IF(D15<=E15,"⚠️ STOCK BAJO","✅ OK")) -> ❌ SIN STOCK
A16: Nueces | B16: 0 | C16: =SUMIF('🛒 Ventas del Día'!D$4:D$107,"Nueces 100g",'🛒 Ventas del Día'!F$4:F$107)*0.1+SUMIF('🛒 Ventas del Día'!D$4:D$107,"Nueces 250g",'🛒 Ventas del Día'!F$4:F$107)*0.25+SUMIF('🛒 Ventas del Día'!D$4:D$107,"Nueces 500g",'🛒 Ventas del Día'!F$4:F$107)*0.5+SUMIF('🛒 Ventas del Día'!D$4:D$107,"Nueces 1kg",'🛒 Ventas del Día'!F$4:F$107)*1 -> 0.42 | D16: =B16-C16 -> -0.42 | E16: 0 | F16: =IF(D16<=0,"❌ SIN STOCK",IF(D16<=E16,"⚠️ STOCK BAJO","✅ OK")) -> ❌ SIN STOCK
A17: Semilla de Zapallo | B17: 0 | C17: =SUMIF('🛒 Ventas del Día'!D$4:D$107,"Semilla de Zapallo 100g",'🛒 Ventas del Día'!F$4:F$107)*0.1+SUMIF('🛒 Ventas del Día'!D$4:D$107,"Semilla de Zapallo 250g",'🛒 Ventas del Día'!F$4:F$107)*0.25+SUMIF('🛒 Ventas del Día'!D$4:D$107,"Semilla de Zapallo 500g",'🛒 Ventas del Día'!F$4:F$107)*0.5+SUMIF('🛒 Ventas del Día'!D$4:D$107,"Semilla de Zapallo 1kg",'🛒 Ventas del Día'!F$4:F$107)*1 -> 0 | D17: =B17-C17 -> 0 | E17: 0 | F17: =IF(D17<=0,"❌ SIN STOCK",IF(D17<=E17,"⚠️ STOCK BAJO","✅ OK")) -> ❌ SIN STOCK
A19: 📦 STOCK POR PRODUCTO INDIVIDUAL
A20: Producto | B20: Categoría | C20: Stock Ini | D20: Vendido | E20: Stock Act | F20: Stock Mín | G20: Estado
A21: (1kg) Aceituna Natural | B21: Aceitunas | C21: 0 | D21: =IFERROR(SUMIF('🛒 Ventas del Día'!D$4:D$107,A21,'🛒 Ventas del Día'!F$4:F$107),0) -> 1 | E21: =C21-D21 -> -1 | F21: 0 | G21: =IF(E21<=0,"❌ SIN STOCK",IF(E21<=F21,"⚠️ STOCK BAJO","✅ OK")) -> ❌ SIN STOCK
A22: (250g) Aceituna Amarga | B22: Aceitunas | C22: 0 | D22: =IFERROR(SUMIF('🛒 Ventas del Día'!D$4:D$107,A22,'🛒 Ventas del Día'!F$4:F$107),0) -> 0 | E22: =C22-D22 -> 0 | F22: 0 | G22: =IF(E22<=0,"❌ SIN STOCK",IF(E22<=F22,"⚠️ STOCK BAJO","✅ OK")) -> ❌ SIN STOCK
A23: (250g) Aceituna Natural | B23: Aceitunas | C23: 0 | D23: =IFERROR(SUMIF('🛒 Ventas del Día'!D$4:D$107,A23,'🛒 Ventas del Día'!F$4:F$107),0) -> 0 | E23: =C23-D23 -> 0 | F23: 0 | G23: =IF(E23<=0,"❌ SIN STOCK",IF(E23<=F23,"⚠️ STOCK BAJO","✅ OK")) -> ❌ SIN STOCK
A24: (250g) Aceituna rellena | B24: Aceitunas | C24: 0 | D24: =IFERROR(SUMIF('🛒 Ventas del Día'!D$4:D$107,A24,'🛒 Ventas del Día'!F$4:F$107),0) -> 0 | E24: =C24-D24 -> 0 | F24: 0 | G24: =IF(E24<=0,"❌ SIN STOCK",IF(E24<=F24,"⚠️ STOCK BAJO","✅ OK")) -> ❌ SIN STOCK
A25: (250g) Pickle | B25: Aceitunas | C25: 0 | D25: =IFERROR(SUMIF('🛒 Ventas del Día'!D$4:D$107,A25,'🛒 Ventas del Día'!F$4:F$107),0) -> 0 | E25: =C25-D25 -> 0 | F25: 0 | G25: =IF(E25<=0,"❌ SIN STOCK",IF(E25<=F25,"⚠️ STOCK BAJO","✅ OK")) -> ❌ SIN STOCK
A26: (500g) Aceituna Amarga | B26: Aceitunas | C26: 0 | D26: =IFERROR(SUMIF('🛒 Ventas del Día'!D$4:D$107,A26,'🛒 Ventas del Día'!F$4:F$107),0) -> 1 | E26: =C26-D26 -> -1 | F26: 0 | G26: =IF(E26<=0,"❌ SIN STOCK",IF(E26<=F26,"⚠️ STOCK BAJO","✅ OK")) -> ❌ SIN STOCK
A27: (500g) Aceituna Natural | B27: Aceitunas | C27: 0 | D27: =IFERROR(SUMIF('🛒 Ventas del Día'!D$4:D$107,A27,'🛒 Ventas del Día'!F$4:F$107),0) -> 0 | E27: =C27-D27 -> 0 | F27: 0 | G27: =IF(E27<=0,"❌ SIN STOCK",IF(E27<=F27,"⚠️ STOCK BAJO","✅ OK")) -> ❌ SIN STOCK
A28: (500g) Aceituna Rellena | B28: Aceitunas | C28: 0 | D28: =IFERROR(SUMIF('🛒 Ventas del Día'!D$4:D$107,A28,'🛒 Ventas del Día'!F$4:F$107),0) -> 0 | E28: =C28-D28 -> 0 | F28: 0 | G28: =IF(E28<=0,"❌ SIN STOCK",IF(E28<=F28,"⚠️ STOCK BAJO","✅ OK")) -> ❌ SIN STOCK
A29: (500g) Pickle | B29: Aceitunas | C29: 0 | D29: =IFERROR(SUMIF('🛒 Ventas del Día'!D$4:D$107,A29,'🛒 Ventas del Día'!F$4:F$107),0) -> 0 | E29: =C29-D29 -> 0 | F29: 0 | G29: =IF(E29<=0,"❌ SIN STOCK",IF(E29<=F29,"⚠️ STOCK BAJO","✅ OK")) -> ❌ SIN STOCK
A30: Chorizo Parrilero 1/2 kg | B30: Embutidos | C30: 0 | D30: =IFERROR(SUMIF('🛒 Ventas del Día'!D$4:D$107,A30,'🛒 Ventas del Día'!F$4:F$107),0) -> 0 | E30: =C30-D30 -> 0 | F30: 0 | G30: =IF(E30<=0,"❌ SIN STOCK",IF(E30<=F30,"⚠️ STOCK BAJO","✅ OK")) -> ❌ SIN STOCK
A31: Chorizo Parrilero 1kg | B31: Embutidos | C31: 0 | D31: =IFERROR(SUMIF('🛒 Ventas del Día'!D$4:D$107,A31,'🛒 Ventas del Día'!F$4:F$107),0) -> 0 | E31: =C31-D31 -> 0 | F31: 0 | G31: =IF(E31<=0,"❌ SIN STOCK",IF(E31<=F31,"⚠️ STOCK BAJO","✅ OK")) -> ❌ SIN STOCK
A32: Longaniza Ahumada 1/2 kg | B32: Embutidos | C32: 0 | D32: =IFERROR(SUMIF('🛒 Ventas del Día'!D$4:D$107,A32,'🛒 Ventas del Día'!F$4:F$107),0) -> 0 | E32: =C32-D32 -> 0 | F32: 0 | G32: =IF(E32<=0,"❌ SIN STOCK",IF(E32<=F32,"⚠️ STOCK BAJO","✅ OK")) -> ❌ SIN STOCK
... A60: Runca 900g | B60: Quesos | C60: 0 | D60: =IFERROR(SUMIF('🛒 Ventas del Día'!D$4:D$107,A60,'🛒 Ventas del Día'!F$4:F$107),0) -> 0 | E60: =C60-D60 -> 0 | F60: 0 | G60: =IF(E60<=0,"❌ SIN STOCK",IF(E60<=F60,"⚠️ STOCK BAJO","✅ OK")) -> ❌ SIN STOCK

Sheet 📈 Dashboard
A1: 📈 DASHBOARD — ANÁLISIS DE RENDIMIENTO
A3: 💰 INGRESOS | C3: 📦 COSTOS | E3: 🏆 GANANCIA | G3: 📊 MARGEN | I3: 🎫 BOLETAS | K3: 🎯 TICKET
A4: ='📊 Resumen Mensual'!C13 -> 362296.5 | C4: ='📊 Resumen Mensual'!D13 -> 259025.22 | E4: ='📊 Resumen Mensual'!E13 -> 103271.28 | G4: ='📊 Resumen Mensual'!F13 -> 0.28504631 | I4: ='📊 Resumen Mensual'!I47 -> 17 | K4: ='📊 Resumen Mensual'!J47 -> 21576.265
A6: 📊 VENTAS POR CATEGORÍA | G6: 💳 MÉTODO DE PAGO Y CLIENTES
A7: Categoría | B7: Ingresos ($) | C7: Ganancia ($) | D7: Margen | E7: % Total | G7: Total Efectivo ($) | J7: =SUMIF('🛒 Ventas del Día'!J$4:J$107,"Efectivo",'🛒 Ventas del Día'!G$4:G$107) -> 25915
A8: Aceitunas | B8: ='📊 Resumen Mensual'!C5 -> 12800 | C8: ='📊 Resumen Mensual'!E5 -> 4800 | D8: ='📊 Resumen Mensual'!F5 -> 0.375 | E8: ='📊 Resumen Mensual'!G5 -> 0.035330178 | G8: Total Tarjeta ($) | J8: =SUMIF('🛒 Ventas del Día'!J$4:J$107,"Tarjeta",'🛒 Ventas del Día'!G$4:G$107) -> 221331.5
A9: Embutidos | B9: ='📊 Resumen Mensual'!C6 -> 0 | C9: ='📊 Resumen Mensual'!E6 -> 0 | D9: ='📊 Resumen Mensual'!F6 -> 0 | E9: ='📊 Resumen Mensual'!G6 -> 0 | G9: % Efectivo | J9: =IFERROR(J7/(J7+J8),0) -> 0.10481443
A10: Frutos Secos | B10: ='📊 Resumen Mensual'!C7 -> 29396.5 | C10: ='📊 Resumen Mensual'!E7 -> 10490.6 | D10: ='📊 Resumen Mensual'!F7 -> 0.35686561 | E10: ='📊 Resumen Mensual'!G7 -> 0.081139343 | G10: % Tarjeta | J10: =IFERROR(J8/(J7+J8),0) -> 0.89518557
A11: Huevos | B11: ='📊 Resumen Mensual'!C8 -> 262000 | C11: ='📊 Resumen Mensual'!E8 -> 62909 | D11: ='📊 Resumen Mensual'!F8 -> 0.24011069 | E11: ='📊 Resumen Mensual'!G8 -> 0.72316459
A12: Mantequillas | B12: ='📊 Resumen Mensual'!C9 -> 6100 | C12: ='📊 Resumen Mensual'!E9 -> 1735.48 | D12: ='📊 Resumen Mensual'!F9 -> 0.28450492 | E12: ='📊 Resumen Mensual'!G9 -> 0.016837038 | G12: Total Boletas | J12: ='📊 Resumen Mensual'!I47 -> 17
A13: Mermeladas | B13: ='📊 Resumen Mensual'!C10 -> 3500 | C13: ='📊 Resumen Mensual'!E10 -> 1477 | D13: ='📊 Resumen Mensual'!F10 -> 0.422 | E13: ='📊 Resumen Mensual'!G10 -> 0.0096605957 | G13: Ticket Promedio ($) | J13: ='📊 Resumen Mensual'!J47 -> 21576.265
A14: QuesoCabra | B14: ='📊 Resumen Mensual'!C11 -> 11000 | C14: ='📊 Resumen Mensual'!E11 -> 3277.2 | D14: ='📊 Resumen Mensual'!F11 -> 0.29792727 | E14: ='📊 Resumen Mensual'!G11 -> 0.030361872 | G14: Ticket Máximo ($) | J14: =IFERROR(MAX('🛒 Ventas del Día'!K$4:K$107),0) -> 49000
A15: Quesos | B15: ='📊 Resumen Mensual'!C12 -> 37500 | C15: ='📊 Resumen Mensual'!E12 -> 18582 | D15: ='📊 Resumen Mensual'!F12 -> 0.49552 | E15: ='📊 Resumen Mensual'!G12 -> 0.10350638
A17: 🏅 TOP PRODUCTOS MÁS VENDIDOS | G17: 💡 INDICADORES DE DECISIÓN
A18: Producto | B18: Categoría | C18: Cant. | D18: Ingresos ($) | E18: Margen | G18: Indicador | J18: Resultado
A19: Huevo Extra 180u | B19: Huevos | C19: =SUMIF('🛒 Ventas del Día'!D$4:D$107,A19,'🛒 Ventas del Día'!F$4:F$107) -> 2 | D19: =SUMIF('🛒 Ventas del Día'!D$4:D$107,A19,'🛒 Ventas del Día'!G$4:G$107) -> 98000 | E19: 0.22653061 | G19: Cat. más rentable | J19: =INDEX(A8:A15,MATCH(MAX(D8:D15),D8:D15,0)) -> Quesos
A20: Huevo Extra 30u | B20: Huevos | C20: =SUMIF('🛒 Ventas del Día'!D$4:D$107,A20,'🛒 Ventas del Día'!F$4:F$107) -> 9 | D20: =SUMIF('🛒 Ventas del Día'!D$4:D$107,A20,'🛒 Ventas del Día'!G$4:G$107) -> 76950 | E20: 0.26116959 | G20: Cat. menos rentable | J20: =IFERROR(INDEX(A8:A15,MATCH(SMALL(D8:D15,COUNTIF(D8:D15,0)+1),D8:D15,0)),"N/A") -> Huevos
A21: Huevo Super 30u | B21: Huevos | C21: =SUMIF('🛒 Ventas del Día'!D$4:D$107,A21,'🛒 Ventas del Día'!F$4:F$107) -> 4 | D21: =SUMIF('🛒 Ventas del Día'!D$4:D$107,A21,'🛒 Ventas del Día'!G$4:G$107) -> 40000 | E21: 0.19 | G21: Producto estrella | J21: =A19 -> Huevo Extra 180u
A22: Huevo Primera 30u | B22: Huevos | C22: =SUMIF('🛒 Ventas del Día'!D$4:D$107,A22,'🛒 Ventas del Día'!F$4:F$107) -> 5 | D22: =SUMIF('🛒 Ventas del Día'!D$4:D$107,A22,'🛒 Ventas del Día'!G$4:G$107) -> 39000 | E22: 0.25423077 | G22: Ganancia total mes | J22: ='📊 Resumen Mensual'!E13 -> 103271.28
A23: Laminado 470g | B23: Quesos | C23: =SUMIF('🛒 Ventas del Día'!D$4:D$107,A23,'🛒 Ventas del Día'!F$4:F$107) -> 2 | D23: =SUMIF('🛒 Ventas del Día'!D$4:D$107,A23,'🛒 Ventas del Día'!G$4:G$107) -> 13000 | E23: 0.27676923 | G23: Margen global | J23: ='📊 Resumen Mensual'!F13 -> 0.28504631
A24: (1kg) Aceituna Natural | B24: Aceitunas | C24: =SUMIF('🛒 Ventas del Día'!D$4:D$107,A24,'🛒 Ventas del Día'!F$4:F$107) -> 1 | D24: =SUMIF('🛒 Ventas del Día'!D$4:D$107,A24,'🛒 Ventas del Día'!G$4:G$107) -> 8000 | E24: 0.3875
A25: Runca 500g | B25: Quesos | C25: =SUMIF('🛒 Ventas del Día'!D$4:D$107,A25,'🛒 Ventas del Día'!F$4:F$107) -> 1 | D25: =SUMIF('🛒 Ventas del Día'!D$4:D$107,A25,'🛒 Ventas del Día'!G$4:G$107) -> 7500 | E25: 0.360375
A26: miel | B26: Quesos | C26: =SUMIF('🛒 Ventas del Día'!D$4:D$107,A26,'🛒 Ventas del Día'!F$4:F$107) -> 1 | D26: =SUMIF('🛒 Ventas del Día'!D$4:D$107,A26,'🛒 Ventas del Día'!G$4:G$107) -> 7500 | E26: 0
A27: Oregano 200g | B27: QuesoCabra | C27: =SUMIF('🛒 Ventas del Día'!D$4:D$107,A27,'🛒 Ventas del Día'!F$4:F$107) -> 1 | D27: =SUMIF('🛒 Ventas del Día'!D$4:D$107,A27,'🛒 Ventas del Día'!G$4:G$107) -> 5500 | E27: 0.29254545
A28: Natural200g | B28: QuesoCabra | C28: =SUMIF('🛒 Ventas del Día'!D$4:D$107,A28,'🛒 Ventas del Día'!F$4:F$107) -> 1 | D28: =SUMIF('🛒 Ventas del Día'!D$4:D$107,A28,'🛒 Ventas del Día'!G$4:G$107) -> 5500 | E28: 0.30330909
A30: 📅 PROMEDIOS Y TENDENCIAS
A31: Indicador | B31: Valor
A32: Ingresos promedio/día | B32: =IFERROR(AVERAGEIF('📊 Resumen Mensual'!C17:C46,">0"),0) -> 122265.5
A33: Ganancia promedio/día | B33: =IFERROR(AVERAGEIF('📊 Resumen Mensual'!E17:E46,">0"),0) -> 35923.76
A34: Boletas promedio/día | B34: =IFERROR(AVERAGEIF('📊 Resumen Mensual'!I17:I46,">0"),0) -> 17
A35: Días con ventas | B35: =COUNTIF('📊 Resumen Mensual'!C17:C46,">0") -> 3
A36: Mejor día (ingresos) | B36: =MAX('📊 Resumen Mensual'!C17:C46) -> 174629

Sheet 📋 Instrucciones
A1: 📋 INSTRUCCIONES DE USO
B3: PASO 1 — PRODUCTOS
B4: Ve a la pestaña '📦 Productos' y completa el catálogo con todos tus productos:
B5: nombre, categoría, unidad, costo y precio de venta. El margen se calcula solo.
B6: PASO 2 — INVENTARIO
B7: Ve a '📦 Inventario' y registra el stock inicial de cada producto y el stock mínimo
B8: que no quieres que baje. Las alertas se activarán automáticamente.
B9: PASO 3 — VENTAS DIARIAS
B10: Cada día, en '🛒 Ventas del Día', agrega una fila por cada venta:
B11: fecha, nombre del producto (exactamente igual al catálogo), precio y cantidad.
B12: Los totales, costos y ganancias se calculan automáticamente.
B13: PASO 4 — REVISAR RESUMEN
B14: En '📊 Resumen Mensual' puedes ver las ventas agrupadas por categoría y por día.
... B25: • Haz una copia mensual para archivar el historial.

Sheet _Listas
A1: Aceitunas | B1: Embutidos | C1: Frutos_Secos | D1: Huevos | E1: Mantequillas | F1: Mermeladas | G1: QuesoCabra | H1: Quesos
A2: (1kg) Aceituna Natural | B2: Chorizo Parrilero 1/2 kg | C2: Almendras 100g | D2: Huevo Extra 12u | E2: Mantequilla Futurocoop | F2: 0% Frutos del bosque | G2: Albahaca 200g | H2: Ahumado 200g
A3: (250g) Aceituna Amarga | B3: Chorizo Parrilero 1kg | C3: Almendras 1kg | D3: Huevo Extra 15u | E3: Mantequilla Lanalhue | F3: Arandano linaza | G3: Albahaca 420g | H3: Albahaca 200g
A4: (250g) Aceituna Natural | B4: Longaniza Ahumada 1/2 kg | C4: Almendras 250g | D4: Huevo Extra 180u | E4: Mantequilla Rumay | F4: Chimichurri | G4: Merken 200g | H4: Laminado 220g
A5: (250g) Aceituna rellena | B5: Longaniza Ahumada 1kg | C5: Almendras 500g | D5: Huevo Extra 30u | F5: frutos del bosque | G5: Merken 420g | H5: Laminado 470g
A6: (250g) Pickle | B6: Longaniza Tradicional 1/2 kg | C6: Castaña de Cajú 100g | D6: Huevo Extra 6u | F6: Mora, menta, limon | G6: Natural200g | H6: Orégano 200g
A7: (500g) Aceituna Amarga | B7: Longaniza Tradicional 1kg | C7: Castaña de Cajú 1kg | D7: Huevo Jumbo 100u | F7: naranja canrla | G7: Oregano 200g | H7: Orégano Rozagante 200g
A8: (500g) Aceituna Natural | C8: Castaña de Cajú 250g | D8: Huevo Jumbo 20u | F8: Piña,jenjibre, menta | H8: Rozagante 200g
A9: (500g) Aceituna Rellena | C9: Castaña de Cajú 500g | D9: Huevo Primera 12u | H9: Runca 500g
A10: (500g) Pickle | C10: Maní sin Sal 100g | D10: Huevo Primera 15u | H10: Runca 900g
C11: Maní sin Sal 1kg | D11: Huevo Primera 180u
C12: Maní sin Sal 250g | D12: Huevo Primera 30u
C13: Maní sin Sal 500g | D13: Huevo Primera 6u
C14: Mix Regodión 100g | D14: Huevo Super 12u
C15: Mix Regodión 1kg | D15: Huevo Super 15u
C16: Mix Regodión 250g | D16: Huevo Super 180u
C17: Mix Regodión 500g | D17: Huevo Super 30u
C18: Nueces 100g | D18: Huevo Super 6u
C19: Nueces 1kg
C20: Nueces 250g
C21: Nueces 500g
C22: Semilla de Zapallo 100g
C23: Semilla de Zapallo 1kg
C24: Semilla de Zapallo 250g
C25: Semilla de Zapallo 500g
